NoneType: None
NoneType: None
NoneType: None
Traceback (most recent call last):

  File "C:\Users\Sam\AppData\Local\Programs\Python\Python36\lib\site-packages\discord\ext\commands\core.py", line 79, in wrapped
    ret = await coro(*args, **kwargs)

  File "C:\Users\Sam\Desktop\DTWM-Discord-Bot\DTWM-Discord-Bot\Discord_Bot.py", line 242, in fetchAttendance
    return await ctx.send(await bot.get_cog("AttendanceDBWriter").fetchAttendance())

  File "C:\Users\Sam\Desktop\DTWM-Discord-Bot\DTWM-Discord-Bot\DB.py", line 285, in fetchAttendance
    aways = self.doQuery("SELECT away FROM Members where name = ?;", vars = (members, ))

  File "C:\Users\Sam\Desktop\DTWM-Discord-Bot\DTWM-Discord-Bot\DB.py", line 94, in doQuery
    self.cursor.execute(query, vars)

sqlite3.InterfaceError: Error binding parameter 0 - probably unsupported type.
Traceback (most recent call last):

  File "C:\Users\Sam\AppData\Local\Programs\Python\Python36\lib\site-packages\discord\ext\commands\core.py", line 79, in wrapped
    ret = await coro(*args, **kwargs)

  File "C:\Users\Sam\Desktop\DTWM-Discord-Bot\DTWM-Discord-Bot\Discord_Bot.py", line 242, in fetchAttendance
    return await ctx.send(await bot.get_cog("AttendanceDBWriter").fetchAttendance())

  File "C:\Users\Sam\Desktop\DTWM-Discord-Bot\DTWM-Discord-Bot\DB.py", line 295, in fetchAttendance
    attPerMember = [int(value * 100) for value in attPerMember]

  File "C:\Users\Sam\Desktop\DTWM-Discord-Bot\DTWM-Discord-Bot\DB.py", line 295, in <listcomp>
    attPerMember = [int(value * 100) for value in attPerMember]

TypeError: int() argument must be a string, a bytes-like object or a number, not 'list'
Traceback (most recent call last):

  File "C:\Users\Sam\AppData\Local\Programs\Python\Python36\lib\site-packages\discord\ext\commands\core.py", line 79, in wrapped
    ret = await coro(*args, **kwargs)

  File "C:\Users\Sam\Desktop\DTWM-Discord-Bot\DTWM-Discord-Bot\Discord_Bot.py", line 242, in fetchAttendance
    return await ctx.send(await bot.get_cog("AttendanceDBWriter").fetchAttendance())

  File "C:\Users\Sam\Desktop\DTWM-Discord-Bot\DTWM-Discord-Bot\DB.py", line 298, in fetchAttendance
    attPerMember = [int(value * 100) for value in attPerMember]

  File "C:\Users\Sam\Desktop\DTWM-Discord-Bot\DTWM-Discord-Bot\DB.py", line 298, in <listcomp>
    attPerMember = [int(value * 100) for value in attPerMember]

TypeError: int() argument must be a string, a bytes-like object or a number, not 'tuple'
Traceback (most recent call last):

  File "C:\Users\Sam\AppData\Local\Programs\Python\Python36\lib\site-packages\discord\ext\commands\core.py", line 79, in wrapped
    ret = await coro(*args, **kwargs)

  File "C:\Users\Sam\Desktop\DTWM-Discord-Bot\DTWM-Discord-Bot\Discord_Bot.py", line 242, in fetchAttendance
    return await ctx.send(await bot.get_cog("AttendanceDBWriter").fetchAttendance())

  File "C:\Users\Sam\Desktop\DTWM-Discord-Bot\DTWM-Discord-Bot\DB.py", line 298, in fetchAttendance
    attPerMember = [int(value * 100) for value in attPerMember]

  File "C:\Users\Sam\Desktop\DTWM-Discord-Bot\DTWM-Discord-Bot\DB.py", line 298, in <listcomp>
    attPerMember = [int(value * 100) for value in attPerMember]

TypeError: unsupported operand type(s) for *: 'NoneType' and 'int'
Traceback (most recent call last):

  File "C:\Users\Sam\AppData\Local\Programs\Python\Python36\lib\site-packages\discord\ext\commands\core.py", line 79, in wrapped
    ret = await coro(*args, **kwargs)

  File "C:\Users\Sam\Desktop\DTWM-Discord-Bot\DTWM-Discord-Bot\Cogs\Attendance.py", line 357, in do_attendance
    attendees = await self.attendance_inner()

  File "C:\Users\Sam\Desktop\DTWM-Discord-Bot\DTWM-Discord-Bot\Cogs\Attendance.py", line 376, in attendance_inner
    attendees.add(memtils.NameParser(name).parsed())

AttributeError: 'NameParser' object has no attribute 'parsed'
Occured at: 16:17:49.295733Traceback (most recent call last):

  File "C:\Users\Sam\AppData\Local\Programs\Python\Python36\lib\site-packages\discord\ext\commands\core.py", line 79, in wrapped
    ret = await coro(*args, **kwargs)

  File "C:\Users\Sam\Desktop\DTWM-Discord-Bot\DTWM-Discord-Bot\Cogs\Attendance.py", line 357, in do_attendance
    attendees = await self.attendance_inner()

  File "C:\Users\Sam\Desktop\DTWM-Discord-Bot\DTWM-Discord-Bot\Cogs\Attendance.py", line 382, in attendance_inner
    self.db.record_att(attendees)

  File "C:\Users\Sam\Desktop\DTWM-Discord-Bot\DTWM-Discord-Bot\Cogs\Attendance.py", line 143, in record_att
    to_insert, True

  File "C:\Users\Sam\Desktop\DTWM-Discord-Bot\DTWM-Discord-Bot\BenUtils\db.py", line 107, in doQuery
    self.cursor.executemany(query, vars)

sqlite3.IntegrityError: FOREIGN KEY constraint failed
Occured at: 18:26:45.772552Traceback (most recent call last):

  File "C:\Users\Sam\AppData\Local\Programs\Python\Python36\lib\site-packages\discord\ext\commands\core.py", line 79, in wrapped
    ret = await coro(*args, **kwargs)

  File "C:\Users\Sam\Desktop\DTWM-Discord-Bot\DTWM-Discord-Bot\Cogs\Attendance.py", line 357, in do_attendance
    attendees = await self.attendance_inner()

  File "C:\Users\Sam\Desktop\DTWM-Discord-Bot\DTWM-Discord-Bot\Cogs\Attendance.py", line 382, in attendance_inner
    self.db.record_att(attendees)

  File "C:\Users\Sam\Desktop\DTWM-Discord-Bot\DTWM-Discord-Bot\Cogs\Attendance.py", line 143, in record_att
    to_insert, True

  File "C:\Users\Sam\Desktop\DTWM-Discord-Bot\DTWM-Discord-Bot\BenUtils\db.py", line 107, in doQuery
    self.cursor.executemany(query, vars)

sqlite3.IntegrityError: FOREIGN KEY constraint failed
Occured at: 18:26:46.202975Traceback (most recent call last):

  File "C:\Users\Sam\AppData\Local\Programs\Python\Python36\lib\site-packages\discord\ext\commands\core.py", line 79, in wrapped
    ret = await coro(*args, **kwargs)

  File "C:\Users\Sam\Desktop\DTWM-Discord-Bot\DTWM-Discord-Bot\Cogs\Attendance.py", line 357, in do_attendance
    attendees = await self.attendance_inner()

  File "C:\Users\Sam\Desktop\DTWM-Discord-Bot\DTWM-Discord-Bot\Cogs\Attendance.py", line 384, in attendance_inner
    self.db.record_att(attendees)

  File "C:\Users\Sam\Desktop\DTWM-Discord-Bot\DTWM-Discord-Bot\Cogs\Attendance.py", line 143, in record_att
    to_insert, True

  File "C:\Users\Sam\Desktop\DTWM-Discord-Bot\DTWM-Discord-Bot\BenUtils\db.py", line 107, in doQuery
    self.cursor.executemany(query, vars)

sqlite3.IntegrityError: FOREIGN KEY constraint failed
Occured at: 02:57:28.402955Traceback (most recent call last):

  File "C:\Users\Sam\AppData\Local\Programs\Python\Python36\lib\site-packages\discord\ext\commands\core.py", line 79, in wrapped
    ret = await coro(*args, **kwargs)

  File "C:\Users\Sam\Desktop\DTWM-Discord-Bot\DTWM-Discord-Bot\Cogs\Attendance.py", line 314, in add_all_members
    in_outfit = memtils.get_in_outfit()

  File "C:\Users\Sam\Desktop\DTWM-Discord-Bot\DTWM-Discord-Bot\Utils\memtils.py", line 166, in get_in_outfit
    if not common.bot_loaded:

NameError: name 'common' is not defined
Occured at: 05:50:58.708899Traceback (most recent call last):

  File "C:\Users\Sam\AppData\Local\Programs\Python\Python36\lib\site-packages\discord\ext\commands\core.py", line 79, in wrapped
    ret = await coro(*args, **kwargs)

  File "C:\Users\Sam\Desktop\DTWM-Discord-Bot\DTWM-Discord-Bot\Cogs\Attendance.py", line 318, in add_all_members
    for name in in_outfit:

TypeError: 'NoneType' object is not iterable
Occured at: 05:51:54.203977Traceback (most recent call last):

  File "C:\Users\Sam\AppData\Local\Programs\Python\Python36\lib\site-packages\discord\ext\commands\core.py", line 79, in wrapped
    ret = await coro(*args, **kwargs)

  File "C:\Users\Sam\Desktop\DTWM-Discord-Bot\DTWM-Discord-Bot\Cogs\Attendance.py", line 318, in add_all_members
    for name in in_outfit:

TypeError: 'NoneType' object is not iterable
Occured at: 05:53:05.264850Traceback (most recent call last):

  File "C:\Users\Sam\AppData\Local\Programs\Python\Python36\lib\site-packages\discord\ext\commands\core.py", line 79, in wrapped
    ret = await coro(*args, **kwargs)

  File "C:\Users\Sam\Desktop\DTWM-Discord-Bot\DTWM-Discord-Bot\Cogs\Attendance.py", line 319, in add_all_members
    if not self.db.get_member_by_name(name):

  File "C:\Users\Sam\Desktop\DTWM-Discord-Bot\DTWM-Discord-Bot\Cogs\Attendance.py", line 76, in get_member_by_name
    joined_at = D.datetime.strptime(rows[3], "%Y-%m-%d").date()

IndexError: list index out of range
Occured at: 05:54:12.549016Traceback (most recent call last):

  File "C:\Users\Sam\AppData\Local\Programs\Python\Python36\lib\site-packages\discord\ext\commands\core.py", line 79, in wrapped
    ret = await coro(*args, **kwargs)

  File "C:\Users\Sam\Desktop\DTWM-Discord-Bot\DTWM-Discord-Bot\Cogs\Attendance.py", line 319, in add_all_members
    if not self.db.get_member_by_name(name):

  File "C:\Users\Sam\Desktop\DTWM-Discord-Bot\DTWM-Discord-Bot\Cogs\Attendance.py", line 76, in get_member_by_name
    joined_at = D.datetime.strptime(rows[3], "%Y-%m-%d").date()

IndexError: list index out of range
Occured at: 06:00:36.860467Traceback (most recent call last):

  File "C:\Users\Sam\AppData\Local\Programs\Python\Python36\lib\site-packages\discord\ext\commands\core.py", line 79, in wrapped
    ret = await coro(*args, **kwargs)

  File "C:\Users\Sam\Desktop\DTWM-Discord-Bot\DTWM-Discord-Bot\Cogs\Event_handlers.py", line 183, in toggle_reactions
    super().enabled = not self.enabled

AttributeError: 'super' object has no attribute 'enabled'
Occured at: 03:48:20.730702Traceback (most recent call last):

  File "C:\Users\Sam\AppData\Local\Programs\Python\Python36\lib\site-packages\discord\ext\commands\core.py", line 79, in wrapped
    ret = await coro(*args, **kwargs)

  File "C:\Users\Sam\Desktop\DTWM-Discord-Bot\DTWM-Discord-Bot\Cogs\Event_handlers.py", line 183, in toggle_reactions
    super().enabled = not self.enabled

AttributeError: 'super' object has no attribute 'enabled'
Occured at: 03:48:37.132197Traceback (most recent call last):

  File "C:\Users\Sam\AppData\Local\Programs\Python\Python36\lib\site-packages\discord\ext\commands\core.py", line 79, in wrapped
    ret = await coro(*args, **kwargs)

  File "C:\Users\Sam\Desktop\DTWM-Discord-Bot\DTWM-Discord-Bot\Cogs\Event_handlers.py", line 184, in toggle_reactions
    parent.enabled = not self.enabled

AttributeError: 'super' object has no attribute 'enabled'
Occured at: 03:49:17.054536Traceback (most recent call last):

  File "C:\Users\Sam\AppData\Local\Programs\Python\Python36\lib\site-packages\discord\ext\commands\core.py", line 79, in wrapped
    ret = await coro(*args, **kwargs)

  File "C:\Users\Sam\Desktop\DTWM-Discord-Bot\DTWM-Discord-Bot\Cogs\Event_handlers.py", line 185, in toggle_reactions
    super().enabled = not self.enabled

AttributeError: 'super' object has no attribute 'enabled'
Occured at: 03:50:38.792807